Workbook

Sheet Bolão
A1: RODADA 1 | J1: RODADA 2 | S1: RODADA 3 | AC1: Grupo A | AD1: P | AE1: SG | AF1: GP | AI1: Grupo B | AJ1: P | AK1: SG | AL1: GP | BI1: =COUNTIF($AG$38:$AG$45,"A") & COUNTIF($AG$38:$AG$45,"B") & COUNTIF($AG$38:$AG$45,"C") & COUNTIF($AG$38:$AG$45,"D") & COUNTIF($AG$38:$AG$45,"E") & COUNTIF($AG$38:$AG$45,"F") & COUNTIF($AG$38:$AG$45,"G") & COUNTIF($AG$38:$AG$45,"H") & COUNTIF($AG$38:$AG$45,"I") & COUNTIF($AG$38:$AG$45,"J") & COUNTIF($AG$38:$AG$45,"K") & COUNTIF($AG$38:$AG$45,"L") -> 011111011001
A2: Jogo 1 | F2: 46184 | J2: Jogo 25 | O2: 46191 | S2: Jogo 49 | X2: 46197 | AB2: 1 | AC2: =INDEX($AC$80:$AC$83, MATCH(LARGE($AG$80:$AG$83, AB2), $AG$80:$AG$83, 0)) -> México | AD2: =VLOOKUP(AC2, $AC$80:$AF$83, 2, 0) -> 9 | AE2: =VLOOKUP(AC2, $AC$80:$AF$83, 3, 0) -> 8 | AF2: =VLOOKUP(AC2, $AC$80:$AF$83, 4, 0) -> 9 | AH2: 1 | AI2: =INDEX($AI$80:$AI$83, MATCH(LARGE($AM$80:$AM$83, AH2), $AM$80:$AM$83, 0)) -> Suíça | AJ2: =VLOOKUP(AI2, $AI$80:$AL$83, 2, 0) -> 7 | AK2: =VLOOKUP(AI2, $AI$80:$AL$83, 3, 0) -> 5 | AL2: =VLOOKUP(AI2, $AI$80:$AL$83, 4, 0) -> 7
A3: México | B3: 2 | C3: X | D3: 1 | E3: África do Sul | F3: 16:00 | G3: =IF(B3="", 0, IF(B3>D3, 3, IF(B3=D3, 1, 0))) -> 3 | H3: =IF(D3="", 0, IF(D3>B3, 3, IF(D3=B3, 1, 0))) -> 0 | J3: Tchéquia | K3: 1 | L3: X | M3: 2 | N3: África do Sul | O3: 13:00 | P3: =IF(K3="", 0, IF(K3>M3, 3, IF(K3=M3, 1, 0))) -> 0 | Q3: =IF(M3="", 0, IF(M3>K3, 3, IF(M3=K3, 1, 0))) -> 3 | S3: Suíça | T3: 2 | U3: X | V3: 2 | W3: Canadá | X3: 16:00 | Y3: =IF(T3="", 0, IF(T3>V3, 3, IF(T3=V3, 1, 0))) -> 1 | Z3: =IF(V3="", 0, IF(V3>T3, 3, IF(V3=T3, 1, 0))) -> 1 | AB3: 2 | AC3: =INDEX($AC$80:$AC$83, MATCH(LARGE($AG$80:$AG$83, AB3), $AG$80:$AG$83, 0)) -> África do Sul | AD3: =VLOOKUP(AC3, $AC$80:$AF$83, 2, 0) -> 4 | AE3: =VLOOKUP(AC3, $AC$80:$AF$83, 3, 0) -> 0 | AF3: =VLOOKUP(AC3, $AC$80:$AF$83, 4, 0) -> 4 | AH3: 2 | AI3: =INDEX($AI$80:$AI$83, MATCH(LARGE($AM$80:$AM$83, AH3), $AM$80:$AM$83, 0)) -> Catar | AJ3: =VLOOKUP(AI3, $AI$80:$AL$83, 2, 0) -> 4 | AK3: =VLOOKUP(AI3, $AI$80:$AL$83, 3, 0) -> -1 | AL3: =VLOOKUP(AI3, $AI$80:$AL$83, 4, 0) -> 5
A4: Jogo 2 | F4: 46184 | J4: Jogo 26 | O4: 46191 | S4: Jogo 50 | X4: 46197 | AB4: 3 | AC4: =INDEX($AC$80:$AC$83, MATCH(LARGE($AG$80:$AG$83, AB4), $AG$80:$AG$83, 0)) -> Coreia do Sul | AD4: =VLOOKUP(AC4, $AC$80:$AF$83, 2, 0) -> 2 | AE4: =VLOOKUP(AC4, $AC$80:$AF$83, 3, 0) -> -4 | AF4: =VLOOKUP(AC4, $AC$80:$AF$83, 4, 0) -> 1 | AH4: 3 | AI4: =INDEX($AI$80:$AI$83, MATCH(LARGE($AM$80:$AM$83, AH4), $AM$80:$AM$83, 0)) -> Canadá | AJ4: =VLOOKUP(AI4, $AI$80:$AL$83, 2, 0) -> 4 | AK4: =VLOOKUP(AI4, $AI$80:$AL$83, 3, 0) -> -1 | AL4: =VLOOKUP(AI4, $AI$80:$AL$83, 4, 0) -> 3
A5: Coreia do Sul | B5: 0 | C5: X | D5: 0 | E5: Tchéquia | F5: 23:00 | G5: =IF(B5="", 0, IF(B5>D5, 3, IF(B5=D5, 1, 0))) -> 1 | H5: =IF(D5="", 0, IF(D5>B5, 3, IF(D5=B5, 1, 0))) -> 1 | J5: Suíça | K5: 2 | L5: X | M5: 0 | N5: Bósnia e H. | O5: 16:00 | P5: =IF(K5="", 0, IF(K5>M5, 3, IF(K5=M5, 1, 0))) -> 3 | Q5: =IF(M5="", 0, IF(M5>K5, 3, IF(M5=K5, 1, 0))) -> 0 | S5: Bósnia e H. | T5: 3 | U5: X | V5: 3 | W5: Catar | X5: 16:00 | Y5: =IF(T5="", 0, IF(T5>V5, 3, IF(T5=V5, 1, 0))) -> 1 | Z5: =IF(V5="", 0, IF(V5>T5, 3, IF(V5=T5, 1, 0))) -> 1 | AB5: 4 | AC5: =INDEX($AC$80:$AC$83, MATCH(LARGE($AG$80:$AG$83, AB5), $AG$80:$AG$83, 0)) -> Tchéquia | AD5: =VLOOKUP(AC5, $AC$80:$AF$83, 2, 0) -> 1 | AE5: =VLOOKUP(AC5, $AC$80:$AF$83, 3, 0) -> -4 | AF5: =VLOOKUP(AC5, $AC$80:$AF$83, 4, 0) -> 1 | AH5: 4 | AI5: =INDEX($AI$80:$AI$83, MATCH(LARGE($AM$80:$AM$83, AH5), $AM$80:$AM$83, 0)) -> Bósnia e H. | AJ5: =VLOOKUP(AI5, $AI$80:$AL$83, 2, 0) -> 1 | AK5: =VLOOKUP(AI5, $AI$80:$AL$83, 3, 0) -> -3 | AL5: =VLOOKUP(AI5, $AI$80:$AL$83, 4, 0) -> 3
A6: Jogo 3 | F6: 46185 | J6: Jogo 27 | O6: 46191 | S6: Jogo 51 | X6: 46197
A7: Canadá | B7: 1 | C7: X | D7: 0 | E7: Bósnia e H. | F7: 16:00 | G7: =IF(B7="", 0, IF(B7>D7, 3, IF(B7=D7, 1, 0))) -> 3 | H7: =IF(D7="", 0, IF(D7>B7, 3, IF(D7=B7, 1, 0))) -> 0 | J7: Canadá | K7: 0 | L7: X | M7: 2 | N7: Catar | O7: 19:00 | P7: =IF(K7="", 0, IF(K7>M7, 3, IF(K7=M7, 1, 0))) -> 0 | Q7: =IF(M7="", 0, IF(M7>K7, 3, IF(M7=K7, 1, 0))) -> 3 | S7: Marrocos | T7: 2 | U7: X | V7: 1 | W7: Haiti | X7: 19:00 | Y7: =IF(T7="", 0, IF(T7>V7, 3, IF(T7=V7, 1, 0))) -> 3 | Z7: =IF(V7="", 0, IF(V7>T7, 3, IF(V7=T7, 1, 0))) -> 0 | AC7: Grupo C | AD7: P | AE7: SG | AF7: GP | AI7: Grupo D | AJ7: P | AK7: SG | AL7: GP
A8: Jogo 4 | F8: 46185 | J8: Jogo 28 | O8: 46191 | S8: Jogo 52 | X8: 46197 | AB8: 1 | AC8: =INDEX($AO$80:$AO$83, MATCH(LARGE($AS$80:$AS$83, AB8), $AS$80:$AS$83, 0)) -> Brasil | AD8: =VLOOKUP(AC8, $AO$80:$AR$83, 2, 0) -> 9 | AE8: =VLOOKUP(AC8, $AO$80:$AR$83, 3, 0) -> 8 | AF8: =VLOOKUP(AC8, $AO$80:$AR$83, 4, 0) -> 10 | AH8: 1 | AI8: =INDEX($AU$80:$AU$83, MATCH(LARGE($AY$80:$AY$83, AH8), $AY$80:$AY$83, 0)) -> Paraguai | AJ8: =VLOOKUP(AI8, $AU$80:$AX$83, 2, 0) -> 7 | AK8: =VLOOKUP(AI8, $AU$80:$AX$83, 3, 0) -> 5 | AL8: =VLOOKUP(AI8, $AU$80:$AX$83, 4, 0) -> 8
A9: Estados Unidos | B9: 1 | C9: X | D9: 1 | E9: Paraguai | F9: 22:00 | G9: =IF(B9="", 0, IF(B9>D9, 3, IF(B9=D9, 1, 0))) -> 1 | H9: =IF(D9="", 0, IF(D9>B9, 3, IF(D9=B9, 1, 0))) -> 1 | J9: México | K9: 4 | L9: X | M9: 0 | N9: Coreia do Sul | O9: 22:00 | P9: =IF(K9="", 0, IF(K9>M9, 3, IF(K9=M9, 1, 0))) -> 3 | Q9: =IF(M9="", 0, IF(M9>K9, 3, IF(M9=K9, 1, 0))) -> 0 | S9: Escócia | T9: 2 | U9: X | V9: 3 | W9: Brasil | X9: 19:00 | Y9: =IF(T9="", 0, IF(T9>V9, 3, IF(T9=V9, 1, 0))) -> 0 | Z9: =IF(V9="", 0, IF(V9>T9, 3, IF(V9=T9, 1, 0))) -> 3 | AB9: 2 | AC9: =INDEX($AO$80:$AO$83, MATCH(LARGE($AS$80:$AS$83, AB9), $AS$80:$AS$83, 0)) -> Marrocos | AD9: =VLOOKUP(AC9, $AO$80:$AR$83, 2, 0) -> 6 | AE9: =VLOOKUP(AC9, $AO$80:$AR$83, 3, 0) -> 0 | AF9: =VLOOKUP(AC9, $AO$80:$AR$83, 4, 0) -> 4 | AH9: 2 | AI9: =INDEX($AU$80:$AU$83, MATCH(LARGE($AY$80:$AY$83, AH9), $AY$80:$AY$83, 0)) -> Estados Unidos | AJ9: =VLOOKUP(AI9, $AU$80:$AX$83, 2, 0) -> 5 | AK9: =VLOOKUP(AI9, $AU$80:$AX$83, 3, 0) -> 1 | AL9: =VLOOKUP(AI9, $AU$80:$AX$83, 4, 0) -> 5
A10: Jogo 5 | F10: 46186 | J10: Jogo 29 | O10: 46192 | S10: Jogo 53 | X10: 46197 | AB10: 3 | AC10: =INDEX($AO$80:$AO$83, MATCH(LARGE($AS$80:$AS$83, AB10), $AS$80:$AS$83, 0)) -> Escócia | AD10: =VLOOKUP(AC10, $AO$80:$AR$83, 2, 0) -> 3 | AE10: =VLOOKUP(AC10, $AO$80:$AR$83, 3, 0) -> 0 | AF10: =VLOOKUP(AC10, $AO$80:$AR$83, 4, 0) -> 5 | AH10: 3 | AI10: =INDEX($AU$80:$AU$83, MATCH(LARGE($AY$80:$AY$83, AH10), $AY$80:$AY$83, 0)) -> Austrália | AJ10: =VLOOKUP(AI10, $AU$80:$AX$83, 2, 0) -> 2 | AK10: =VLOOKUP(AI10, $AU$80:$AX$83, 3, 0) -> -3 | AL10: =VLOOKUP(AI10, $AU$80:$AX$83, 4, 0) -> 5
A11: Catar | B11: 0 | C11: X | D11: 3 | E11: Suíça | F11: 16:00 | G11: =IF(B11="", 0, IF(B11>D11, 3, IF(B11=D11, 1, 0))) -> 0 | H11: =IF(D11="", 0, IF(D11>B11, 3, IF(D11=B11, 1, 0))) -> 3 | J11: Estados Unidos | K11: 2 | L11: X | M11: 2 | N11: Austrália | O11: 16:00 | P11: =IF(K11="", 0, IF(K11>M11, 3, IF(K11=M11, 1, 0))) -> 1 | Q11: =IF(M11="", 0, IF(M11>K11, 3, IF(M11=K11, 1, 0))) -> 1 | S11: África do Sul | T11: 1 | U11: X | V11: 1 | W11: Coreia do Sul | X11: 22:00 | Y11: =IF(T11="", 0, IF(T11>V11, 3, IF(T11=V11, 1, 0))) -> 1 | Z11: =IF(V11="", 0, IF(V11>T11, 3, IF(V11=T11, 1, 0))) -> 1 | AB11: 4 | AC11: =INDEX($AO$80:$AO$83, MATCH(LARGE($AS$80:$AS$83, AB11), $AS$80:$AS$83, 0)) -> Haiti | AD11: =VLOOKUP(AC11, $AO$80:$AR$83, 2, 0) -> 0 | AE11: =VLOOKUP(AC11, $AO$80:$AR$83, 3, 0) -> -10 | AF11: =VLOOKUP(AC11, $AO$80:$AR$83, 4, 0) -> 1 | AH11: 4 | AI11: =INDEX($AU$80:$AU$83, MATCH(LARGE($AY$80:$AY$83, AH11), $AY$80:$AY$83, 0)) -> Turquia | AJ11: =VLOOKUP(AI11, $AU$80:$AX$83, 2, 0) -> 1 | AK11: =VLOOKUP(AI11, $AU$80:$AX$83, 3, 0) -> -3 | AL11: =VLOOKUP(AI11, $AU$80:$AX$83, 4, 0) -> 4
A12: Jogo 6 | F12: 46186 | J12: Jogo 30 | O12: 46192 | S12: Jogo 54 | X12: 46197
A13: Brasil | B13: 2 | C13: X | D13: 0 | E13: Marrocos | F13: 19:00 | G13: =IF(B13="", 0, IF(B13>D13, 3, IF(B13=D13, 1, 0))) -> 3 | H13: =IF(D13="", 0, IF(D13>B13, 3, IF(D13=B13, 1, 0))) -> 0 | J13: Escócia | K13: 1 | L13: X | M13: 2 | N13: Marrocos | O13: 19:00 | P13: =IF(K13="", 0, IF(K13>M13, 3, IF(K13=M13, 1, 0))) -> 0 | Q13: =IF(M13="", 0, IF(M13>K13, 3, IF(M13=K13, 1, 0))) -> 3 | S13: Tchéquia | T13: 0 | U13: X | V13: 3 | W13: México | X13: 22:00 | Y13: =IF(T13="", 0, IF(T13>V13, 3, IF(T13=V13, 1, 0))) -> 0 | Z13: =IF(V13="", 0, IF(V13>T13, 3, IF(V13=T13, 1, 0))) -> 3 | AC13: Grupo E | AD13: P | AE13: SG | AF13: GP | AI13: Grupo F | AJ13: P | AK13: SG | AL13: GP
A14: Jogo 7 | F14: 46186 | J14: Jogo 31 | O14: 46192 | S14: Jogo 55 | X14: 46198 | AB14: 1 | AC14: =INDEX($AC$86:$AC$89, MATCH(LARGE($AG$86:$AG$89, AB14), $AG$86:$AG$89, 0)) -> Alemanha | AD14: =VLOOKUP(AC14, $AC$86:$AF$89, 2, 0) -> 7 | AE14: =VLOOKUP(AC14, $AC$86:$AF$89, 3, 0) -> 8 | AF14: =VLOOKUP(AC14, $AC$86:$AF$89, 4, 0) -> 11 | AH14: 1 | AI14: =INDEX($AI$86:$AI$89, MATCH(LARGE($AM$86:$AM$89, AH14), $AM$86:$AM$89, 0)) -> Japão | AJ14: =VLOOKUP(AI14, $AI$86:$AL$89, 2, 0) -> 7 | AK14: =VLOOKUP(AI14, $AI$86:$AL$89, 3, 0) -> 3 | AL14: =VLOOKUP(AI14, $AI$86:$AL$89, 4, 0) -> 6
A15: Haiti | B15: 0 | C15: X | D15: 4 | E15: Escócia | F15: 22:00 | G15: =IF(B15="", 0, IF(B15>D15, 3, IF(B15=D15, 1, 0))) -> 0 | H15: =IF(D15="", 0, IF(D15>B15, 3, IF(D15=B15, 1, 0))) -> 3 | J15: Brasil | K15: 5 | L15: X | M15: 0 | N15: Haiti | O15: 21:30 | P15: =IF(K15="", 0, IF(K15>M15, 3, IF(K15=M15, 1, 0))) -> 3 | Q15: =IF(M15="", 0, IF(M15>K15, 3, IF(M15=K15, 1, 0))) -> 0 | S15: Curaçao | T15: 0 | U15: X | V15: 3 | W15: Costa do Marfim | X15: 17:00 | Y15: =IF(T15="", 0, IF(T15>V15, 3, IF(T15=V15, 1, 0))) -> 0 | Z15: =IF(V15="", 0, IF(V15>T15, 3, IF(V15=T15, 1, 0))) -> 3 | AB15: 2 | AC15: =INDEX($AC$86:$AC$89, MATCH(LARGE($AG$86:$AG$89, AB15), $AG$86:$AG$89, 0)) -> Equador | AD15: =VLOOKUP(AC15, $AC$86:$AF$89, 2, 0) -> 7 | AE15: =VLOOKUP(AC15, $AC$86:$AF$89, 3, 0) -> 6 | AF15: =VLOOKUP(AC15, $AC$86:$AF$89, 4, 0) -> 8 | AH15: 2 | AI15: =INDEX($AI$86:$AI$89, MATCH(LARGE($AM$86:$AM$89, AH15), $AM$86:$AM$89, 0)) -> Holanda | AJ15: =VLOOKUP(AI15, $AI$86:$AL$89, 2, 0) -> 5 | AK15: =VLOOKUP(AI15, $AI$86:$AL$89, 3, 0) -> 1 | AL15: =VLOOKUP(AI15, $AI$86:$AL$89, 4, 0) -> 4
A16: Jogo 8 | F16: 46187 | J16: Jogo 32 | O16: 46193 | S16: Jogo 56 | X16: 46198 | AB16: 3 | AC16: =INDEX($AC$86:$AC$89, MATCH(LARGE($AG$86:$AG$89, AB16), $AG$86:$AG$89, 0)) -> Costa do Marfim | AD16: =VLOOKUP(AC16, $AC$86:$AF$89, 2, 0) -> 3 | AE16: =VLOOKUP(AC16, $AC$86:$AF$89, 3, 0) -> -1 | AF16: =VLOOKUP(AC16, $AC$86:$AF$89, 4, 0) -> 4 | AH16: 3 | AI16: =INDEX($AI$86:$AI$89, MATCH(LARGE($AM$86:$AM$89, AH16), $AM$86:$AM$89, 0)) -> Suécia | AJ16: =VLOOKUP(AI16, $AI$86:$AL$89, 2, 0) -> 4 | AK16: =VLOOKUP(AI16, $AI$86:$AL$89, 3, 0) -> -1 | AL16: =VLOOKUP(AI16, $AI$86:$AL$89, 4, 0) -> 4
A17: Austrália | B17: 2 | C17: X | D17: 2 | E17: Turquia | F17: 01:00 | G17: =IF(B17="", 0, IF(B17>D17, 3, IF(B17=D17, 1, 0))) -> 1 | H17: =IF(D17="", 0, IF(D17>B17, 3, IF(D17=B17, 1, 0))) -> 1 | J17: Turquia | K17: 1 | L17: X | M17: 3 | N17: Paraguai | O17: 00:00 | P17: =IF(K17="", 0, IF(K17>M17, 3, IF(K17=M17, 1, 0))) -> 0 | Q17: =IF(M17="", 0, IF(M17>K17, 3, IF(M17=K17, 1, 0))) -> 3 | S17: Equador | T17: 2 | U17: X | V17: 2 | W17: Alemanha | X17: 17:00 | Y17: =IF(T17="", 0, IF(T17>V17, 3, IF(T17=V17, 1, 0))) -> 1 | Z17: =IF(V17="", 0, IF(V17>T17, 3, IF(V17=T17, 1, 0))) -> 1 | AB17: 4 | AC17: =INDEX($AC$86:$AC$89, MATCH(LARGE($AG$86:$AG$89, AB17), $AG$86:$AG$89, 0)) -> Curaçao | AD17: =VLOOKUP(AC17, $AC$86:$AF$89, 2, 0) -> 0 | AE17: =VLOOKUP(AC17, $AC$86:$AF$89, 3, 0) -> -13 | AF17: =VLOOKUP(AC17, $AC$86:$AF$89, 4, 0) -> 0 | AH17: 4 | AI17: =INDEX($AI$86:$AI$89, MATCH(LARGE($AM$86:$AM$89, AH17), $AM$86:$AM$89, 0)) -> Tunísia | AJ17: =VLOOKUP(AI17, $AI$86:$AL$89, 2, 0) -> 0 | AK17: =VLOOKUP(AI17, $AI$86:$AL$89, 3, 0) -> -3 | AL17: =VLOOKUP(AI17, $AI$86:$AL$89, 4, 0) -> 1
A18: Jogo 9 | F18: 46187 | J18: Jogo 33 | O18: 46193 | S18: Jogo 57 | X18: 46198
A19: Alemanha | B19: 6 | C19: X | D19: 0 | E19: Curaçao | F19: 14:00 | G19: =IF(B19="", 0, IF(B19>D19, 3, IF(B19=D19, 1, 0))) -> 3 | H19: =IF(D19="", 0, IF(D19>B19, 3, IF(D19=B19, 1, 0))) -> 0 | J19: Holanda | K19: 2 | L19: X | M19: 2 | N19: Suécia | O19: 14:00 | P19: =IF(K19="", 0, IF(K19>M19, 3, IF(K19=M19, 1, 0))) -> 1 | Q19: =IF(M19="", 0, IF(M19>K19, 3, IF(M19=K19, 1, 0))) -> 1 | S19: Tunísia | T19: 0 | U19: X | V19: 1 | W19: Holanda | X19: 20:00 | Y19: =IF(T19="", 0, IF(T19>V19, 3, IF(T19=V19, 1, 0))) -> 0 | Z19: =IF(V19="", 0, IF(V19>T19, 3, IF(V19=T19, 1, 0))) -> 3 | AC19: Grupo G | AD19: P | AE19: SG | AF19: GP | AI19: Grupo H | AJ19: P | AK19: SG | AL19: GP
A20: Jogo 10 | F20: 46187 | J20: Jogo 34 | O20: 46193 | S20: Jogo 58 | X20: 46198 | AB20: 1 | AC20: =INDEX($AO$86:$AO$89, MATCH(LARGE($AS$86:$AS$89, AB20), $AS$86:$AS$89, 0)) -> Bélgica | AD20: =VLOOKUP(AC20, $AO$86:$AR$89, 2, 0) -> 9 | AE20: =VLOOKUP(AC20, $AO$86:$AR$89, 3, 0) -> 7 | AF20: =VLOOKUP(AC20, $AO$86:$AR$89, 4, 0) -> 8 | AH20: 1 | AI20: =INDEX($AU$86:$AU$89, MATCH(LARGE($AY$86:$AY$89, AH20), $AY$86:$AY$89, 0)) -> Espanha | AJ20: =VLOOKUP(AI20, $AU$86:$AX$89, 2, 0) -> 7 | AK20: =VLOOKUP(AI20, $AU$86:$AX$89, 3, 0) -> 4 | AL20: =VLOOKUP(AI20, $AU$86:$AX$89, 4, 0) -> 6
A21: Holanda | B21: 1 | C21: X | D21: 1 | E21: Japão | F21: 17:00 | G21: =IF(B21="", 0, IF(B21>D21, 3, IF(B21=D21, 1, 0))) -> 1 | H21: =IF(D21="", 0, IF(D21>B21, 3, IF(D21=B21, 1, 0))) -> 1 | J21: Alemanha | K21: 3 | L21: X | M21: 1 | N21: Costa do Marfim | O21: 17:00 | P21: =IF(K21="", 0, IF(K21>M21, 3, IF(K21=M21, 1, 0))) -> 3 | Q21: =IF(M21="", 0, IF(M21>K21, 3, IF(M21=K21, 1, 0))) -> 0 | S21: Japão | T21: 3 | U21: X | V21: 1 | W21: Suécia | X21: 20:00 | Y21: =IF(T21="", 0, IF(T21>V21, 3, IF(T21=V21, 1, 0))) -> 3 | Z21: =IF(V21="", 0, IF(V21>T21, 3, IF(V21=T21, 1, 0))) -> 0 | AB21: 2 | AC21: =INDEX($AO$86:$AO$89, MATCH(LARGE($AS$86:$AS$89, AB21), $AS$86:$AS$89, 0)) -> Egito | AD21: =VLOOKUP(AC21, $AO$86:$AR$89, 2, 0) -> 6 | AE21: =VLOOKUP(AC21, $AO$86:$AR$89, 3, 0) -> 0 | AF21: =VLOOKUP(AC21, $AO$86:$AR$89, 4, 0) -> 2 | AH21: 2 | AI21: =INDEX($AU$86:$AU$89, MATCH(LARGE($AY$86:$AY$89, AH21), $AY$86:$AY$89, 0)) -> Uruguai | AJ21: =VLOOKUP(AI21, $AU$86:$AX$89, 2, 0) -> 5 | AK21: =VLOOKUP(AI21, $AU$86:$AX$89, 3, 0) -> 3 | AL21: =VLOOKUP(AI21, $AU$86:$AX$89, 4, 0) -> 5
A22: Jogo 11 | F22: 46187 | J22: Jogo 35 | O22: 46193 | S22: Jogo 59 | X22: 46198 | AB22: 3 | AC22: =INDEX($AO$86:$AO$89, MATCH(LARGE($AS$86:$AS$89, AB22), $AS$86:$AS$89, 0)) -> Irã | AD22: =VLOOKUP(AC22, $AO$86:$AR$89, 2, 0) -> 1 | AE22: =VLOOKUP(AC22, $AO$86:$AR$89, 3, 0) -> -3 | AF22: =VLOOKUP(AC22, $AO$86:$AR$89, 4, 0) -> 1 | AH22: 3 | AI22: =INDEX($AU$86:$AU$89, MATCH(LARGE($AY$86:$AY$89, AH22), $AY$86:$AY$89, 0)) -> Arábia Saudita | AJ22: =VLOOKUP(AI22, $AU$86:$AX$89, 2, 0) -> 4 | AK22: =VLOOKUP(AI22, $AU$86:$AX$89, 3, 0) -> 2 | AL22: =VLOOKUP(AI22, $AU$86:$AX$89, 4, 0) -> 5
A23: Costa do Marfim | B23: 0 | C23: X | D23: 2 | E23: Equador | F23: 20:00 | G23: =IF(B23="", 0, IF(B23>D23, 3, IF(B23=D23, 1, 0))) -> 0 | H23: =IF(D23="", 0, IF(D23>B23, 3, IF(D23=B23, 1, 0))) -> 3 | J23: Equador | K23: 4 | L23: X | M23: 0 | N23: Curaçao | O23: 21:00 | P23: =IF(K23="", 0, IF(K23>M23, 3, IF(K23=M23, 1, 0))) -> 3 | Q23: =IF(M23="", 0, IF(M23>K23, 3, IF(M23=K23, 1, 0))) -> 0 | S23: Turquia | T23: 1 | U23: X | V23: 2 | W23: Estados Unidos | X23: 23:00 | Y23: =IF(T23="", 0, IF(T23>V23, 3, IF(T23=V23, 1, 0))) -> 0 | Z23: =IF(V23="", 0, IF(V23>T23, 3, IF(V23=T23, 1, 0))) -> 3 | AB23: 4 | AC23: =INDEX($AO$86:$AO$89, MATCH(LARGE($AS$86:$AS$89, AB23), $AS$86:$AS$89, 0)) -> Nova Zelândia | AD23: =VLOOKUP(AC23, $AO$86:$AR$89, 2, 0) -> 1 | AE23: =VLOOKUP(AC23, $AO$86:$AR$89, 3, 0) -> -4 | AF23: =VLOOKUP(AC23, $AO$86:$AR$89, 4, 0) -> 0 | AH23: 4 | AI23: =INDEX($AU$86:$AU$89, MATCH(LARGE($AY$86:$AY$89, AH23), $AY$86:$AY$89, 0)) -> Cabo Verde | AJ23: =VLOOKUP(AI23, $AU$86:$AX$89, 2, 0) -> 0 | AK23: =VLOOKUP(AI23, $AU$86:$AX$89, 3, 0) -> -9 | AL23: =VLOOKUP(AI23, $AU$86:$AX$89, 4, 0) -> 0
A24: Jogo 12 | F24: 46187 | J24: Jogo 36 | O24: 46194 | S24: Jogo 60 | X24: 46198
A25: Suécia | B25: 1 | C25: X | D25: 0 | E25: Tunísia | F25: 23:00 | G25: =IF(B25="", 0, IF(B25>D25, 3, IF(B25=D25, 1, 0))) -> 3 | H25: =IF(D25="", 0, IF(D25>B25, 3, IF(D25=B25, 1, 0))) -> 0 | J25: Tunísia | K25: 1 | L25: X | M25: 2 | N25: Japão | O25: 01:00 | P25: =IF(K25="", 0, IF(K25>M25, 3, IF(K25=M25, 1, 0))) -> 0 | Q25: =IF(M25="", 0, IF(M25>K25, 3, IF(M25=K25, 1, 0))) -> 3 | S25: Paraguai | T25: 4 | U25: X | V25: 1 | W25: Austrália | X25: 23:00 | Y25: =IF(T25="", 0, IF(T25>V25, 3, IF(T25=V25, 1, 0))) -> 3 | Z25: =IF(V25="", 0, IF(V25>T25, 3, IF(V25=T25, 1, 0))) -> 0 | AC25: Grupo I | AD25: P | AE25: SG | AF25: GP | AI25: Grupo J | AJ25: P | AK25: SG | AL25: GP
A26: Jogo 13 | F26: 46188 | J26: Jogo 37 | O26: 46194 | S26: Jogo 61 | X26: 46199 | AB26: 1 | AC26: =INDEX($AC$92:$AC$95, MATCH(LARGE($AG$92:$AG$95, AB26), $AG$92:$AG$95, 0)) -> França | AD26: =VLOOKUP(AC26, $AC$92:$AF$95, 2, 0) -> 9 | AE26: =VLOOKUP(AC26, $AC$92:$AF$95, 3, 0) -> 8 | AF26: =VLOOKUP(AC26, $AC$92:$AF$95, 4, 0) -> 10 | AH26: 1 | AI26: =INDEX($AI$92:$AI$95, MATCH(LARGE($AM$92:$AM$95, AH26), $AM$92:$AM$95, 0)) -> Argentina | AJ26: =VLOOKUP(AI26, $AI$92:$AL$95, 2, 0) -> 9 | AK26: =VLOOKUP(AI26, $AI$92:$AL$95, 3, 0) -> 8 | AL26: =VLOOKUP(AI26, $AI$92:$AL$95, 4, 0) -> 9
A27: Espanha | B27: 3 | C27: X | D27: 0 | E27: Cabo Verde | F27: 13:00 | G27: =IF(B27="", 0, IF(B27>D27, 3, IF(B27=D27, 1, 0))) -> 3 | H27: =IF(D27="", 0, IF(D27>B27, 3, IF(D27=B27, 1, 0))) -> 0 | J27: Espanha | K27: 2 | L27: X | M27: 1 | N27: Arábia Saudita | O27: 13:00 | P27: =IF(K27="", 0, IF(K27>M27, 3, IF(K27=M27, 1, 0))) -> 3 | Q27: =IF(M27="", 0, IF(M27>K27, 3, IF(M27=K27, 1, 0))) -> 0 | S27: Noruega | T27: 1 | U27: X | V27: 3 | W27: França | X27: 16:00 | Y27: =IF(T27="", 0, IF(T27>V27, 3, IF(T27=V27, 1, 0))) -> 0 | Z27: =IF(V27="", 0, IF(V27>T27, 3, IF(V27=T27, 1, 0))) -> 3 | AB27: 2 | AC27: =INDEX($AC$92:$AC$95, MATCH(LARGE($AG$92:$AG$95, AB27), $AG$92:$AG$95, 0)) -> Noruega | AD27: =VLOOKUP(AC27, $AC$92:$AF$95, 2, 0) -> 4 | AE27: =VLOOKUP(AC27, $AC$92:$AF$95, 3, 0) -> 1 | AF27: =VLOOKUP(AC27, $AC$92:$AF$95, 4, 0) -> 6 | AH27: 2 | AI27: =INDEX($AI$92:$AI$95, MATCH(LARGE($AM$92:$AM$95, AH27), $AM$92:$AM$95, 0)) -> Argélia | AJ27: =VLOOKUP(AI27, $AI$92:$AL$95, 2, 0) -> 6 | AK27: =VLOOKUP(AI27, $AI$92:$AL$95, 3, 0) -> 1 | AL27: =VLOOKUP(AI27, $AI$92:$AL$95, 4, 0) -> 4
A28: Jogo 14 | F28: 46188 | J28: Jogo 38 | O28: 46194 | S28: Jogo 62 | X28: 46199 | AB28: 3 | AC28: =INDEX($AC$92:$AC$95, MATCH(LARGE($AG$92:$AG$95, AB28), $AG$92:$AG$95, 0)) -> Senegal | AD28: =VLOOKUP(AC28, $AC$92:$AF$95, 2, 0) -> 4 | AE28: =VLOOKUP(AC28, $AC$92:$AF$95, 3, 0) -> -1 | AF28: =VLOOKUP(AC28, $AC$92:$AF$95, 4, 0) -> 4 | AH28: 3 | AI28: =INDEX($AI$92:$AI$95, MATCH(LARGE($AM$92:$AM$95, AH28), $AM$92:$AM$95, 0)) -> Áustria | AJ28: =VLOOKUP(AI28, $AI$92:$AL$95, 2, 0) -> 1 | AK28: =VLOOKUP(AI28, $AI$92:$AL$95, 3, 0) -> -4 | AL28: =VLOOKUP(AI28, $AI$92:$AL$95, 4, 0) -> 3
A29: Bélgica | B29: 2 | C29: X | D29: 0 | E29: Egito | F29: 16:00 | G29: =IF(B29="", 0, IF(B29>D29, 3, IF(B29=D29, 1, 0))) -> 3 | H29: =IF(D29="", 0, IF(D29>B29, 3, IF(D29=B29, 1, 0))) -> 0 | J29: Bélgica | K29: 3 | L29: X | M29: 1 | N29: Irã | O29: 16:00 | P29: =IF(K29="", 0, IF(K29>M29, 3, IF(K29=M29, 1, 0))) -> 3 | Q29: =IF(M29="", 0, IF(M29>K29, 3, IF(M29=K29, 1, 0))) -> 0 | S29: Senegal | T29: 1 | U29: X | V29: 0 | W29: Iraque | X29: 16:00 | Y29: =IF(T29="", 0, IF(T29>V29, 3, IF(T29=V29, 1, 0))) -> 3 | Z29: =IF(V29="", 0, IF(V29>T29, 3, IF(V29=T29, 1, 0))) -> 0 | AB29: 4 | AC29: =INDEX($AC$92:$AC$95, MATCH(LARGE($AG$92:$AG$95, AB29), $AG$92:$AG$95, 0)) -> Iraque | AD29: =VLOOKUP(AC29, $AC$92:$AF$95, 2, 0) -> 0 | AE29: =VLOOKUP(AC29, $AC$92:$AF$95, 3, 0) -> -8 | AF29: =VLOOKUP(AC29, $AC$92:$AF$95, 4, 0) -> 0 | AH29: 4 | AI29: =INDEX($AI$92:$AI$95, MATCH(LARGE($AM$92:$AM$95, AH29), $AM$92:$AM$95, 0)) -> Jordânia | AJ29: =VLOOKUP(AI29, $AI$92:$AL$95, 2, 0) -> 1 | AK29: =VLOOKUP(AI29, $AI$92:$AL$95, 3, 0) -> -5 | AL29: =VLOOKUP(AI29, $AI$92:$AL$95, 4, 0) -> 3
A30: Jogo 15 | F30: 46188 | J30: Jogo 39 | O30: 46194 | S30: Jogo 63 | X30: 46199
A31: Arábia Saudita | B31: 1 | C31: X | D31: 1 | E31: Uruguai | F31: 19:00 | G31: =IF(B31="", 0, IF(B31>D31, 3, IF(B31=D31, 1, 0))) -> 1 | H31: =IF(D31="", 0, IF(D31>B31, 3, IF(D31=B31, 1, 0))) -> 1 | J31: Uruguai | K31: 3 | L31: X | M31: 0 | N31: Cabo Verde | O31: 19:00 | P31: =IF(K31="", 0, IF(K31>M31, 3, IF(K31=M31, 1, 0))) -> 3 | Q31: =IF(M31="", 0, IF(M31>K31, 3, IF(M31=K31, 1, 0))) -> 0 | S31: Cabo Verde | T31: 0 | U31: X | V31: 3 | W31: Arábia Saudita | X31: 21:00 | Y31: =IF(T31="", 0, IF(T31>V31, 3, IF(T31=V31, 1, 0))) -> 0 | Z31: =IF(V31="", 0, IF(V31>T31, 3, IF(V31=T31, 1, 0))) -> 3 | AC31: Grupo K | AD31: P | AE31: SG | AF31: GP | AI31: Grupo L | AJ31: P | AK31: SG | AL31: GP
A32: Jogo 16 | F32: 46188 | J32: Jogo 40 | O32: 46194 | S32: Jogo 64 | X32: 46199 | AB32: 1 | AC32: =INDEX($AO$92:$AO$95, MATCH(LARGE($AS$92:$AS$95, AB32), $AS$92:$AS$95, 0)) -> Colômbia | AD32: =VLOOKUP(AC32, $AO$92:$AR$95, 2, 0) -> 7 | AE32: =VLOOKUP(AC32, $AO$92:$AR$95, 3, 0) -> 10 | AF32: =VLOOKUP(AC32, $AO$92:$AR$95, 4, 0) -> 10 | AH32: 1 | AI32: =INDEX($AU$92:$AU$95, MATCH(LARGE($AY$92:$AY$95, AH32), $AY$92:$AY$95, 0)) -> Inglaterra | AJ32: =VLOOKUP(AI32, $AU$92:$AX$95, 2, 0) -> 7 | AK32: =VLOOKUP(AI32, $AU$92:$AX$95, 3, 0) -> 9 | AL32: =VLOOKUP(AI32, $AU$92:$AX$95, 4, 0) -> 9
A33: Irã | B33: 0 | C33: X | D33: 0 | E33: Nova Zelândia | F33: 22:00 | G33: =IF(B33="", 0, IF(B33>D33, 3, IF(B33=D33, 1, 0))) -> 1 | H33: =IF(D33="", 0, IF(D33>B33, 3, IF(D33=B33, 1, 0))) -> 1 | J33: Nova Zelândia | K33: 0 | L33: X | M33: 1 | N33: Egito | O33: 22:00 | P33: =IF(K33="", 0, IF(K33>M33, 3, IF(K33=M33, 1, 0))) -> 0 | Q33: =IF(M33="", 0, IF(M33>K33, 3, IF(M33=K33, 1, 0))) -> 3 | S33: Uruguai | T33: 1 | U33: X | V33: 1 | W33: Espanha | X33: 21:00 | Y33: =IF(T33="", 0, IF(T33>V33, 3, IF(T33=V33, 1, 0))) -> 1 | Z33: =IF(V33="", 0, IF(V33>T33, 3, IF(V33=T33, 1, 0))) -> 1 | AB33: 2 | AC33: =INDEX($AO$92:$AO$95, MATCH(LARGE($AS$92:$AS$95, AB33), $AS$92:$AS$95, 0)) -> Portugal | AD33: =VLOOKUP(AC33, $AO$92:$AR$95, 2, 0) -> 7 | AE33: =VLOOKUP(AC33, $AO$92:$AR$95, 3, 0) -> 7 | AF33: =VLOOKUP(AC33, $AO$92:$AR$95, 4, 0) -> 7 | AH33: 2 | AI33: =INDEX($AU$92:$AU$95, MATCH(LARGE($AY$92:$AY$95, AH33), $AY$92:$AY$95, 0)) -> Croácia | AJ33: =VLOOKUP(AI33, $AU$92:$AX$95, 2, 0) -> 7 | AK33: =VLOOKUP(AI33, $AU$92:$AX$95, 3, 0) -> 8 | AL33: =VLOOKUP(AI33, $AU$92:$AX$95, 4, 0) -> 8
A34: Jogo 17 | F34: 46189 | J34: Jogo 41 | O34: 46195 | S34: Jogo 65 | X34: 46200 | AB34: 3 | AC34: =INDEX($AO$92:$AO$95, MATCH(LARGE($AS$92:$AS$95, AB34), $AS$92:$AS$95, 0)) -> Uzbequistão | AD34: =VLOOKUP(AC34, $AO$92:$AR$95, 2, 0) -> 1 | AE34: =VLOOKUP(AC34, $AO$92:$AR$95, 3, 0) -> -8 | AF34: =VLOOKUP(AC34, $AO$92:$AR$95, 4, 0) -> 2 | AH34: 3 | AI34: =INDEX($AU$92:$AU$95, MATCH(LARGE($AY$92:$AY$95, AH34), $AY$92:$AY$95, 0)) -> Gana | AJ34: =VLOOKUP(AI34, $AU$92:$AX$95, 2, 0) -> 3 | AK34: =VLOOKUP(AI34, $AU$92:$AX$95, 3, 0) -> -8 | AL34: =VLOOKUP(AI34, $AU$92:$AX$95, 4, 0) -> 3
A35: França | B35: 3 | C35: X | D35: 1 | E35: Senegal | F35: 16:00 | G35: =IF(B35="", 0, IF(B35>D35, 3, IF(B35=D35, 1, 0))) -> 3 | H35: =IF(D35="", 0, IF(D35>B35, 3, IF(D35=B35, 1, 0))) -> 0 | J35: Argentina | K35: 3 | L35: X | M35: 1 | N35: Áustria | O35: 14:00 | P35: =IF(K35="", 0, IF(K35>M35, 3, IF(K35=M35, 1, 0))) -> 3 | Q35: =IF(M35="", 0, IF(M35>K35, 3, IF(M35=K35, 1, 0))) -> 0 | S35: Nova Zelândia | T35: 0 | U35: X | V35: 3 | W35: Bélgica | X35: 00:00 | Y35: =IF(T35="", 0, IF(T35>V35, 3, IF(T35=V35, 1, 0))) -> 0 | Z35: =IF(V35="", 0, IF(V35>T35, 3, IF(V35=T35, 1, 0))) -> 3 | AB35: 4 | AC35: =INDEX($AO$92:$AO$95, MATCH(LARGE($AS$92:$AS$95, AB35), $AS$92:$AS$95, 0)) -> RD Congo | AD35: =VLOOKUP(AC35, $AO$92:$AR$95, 2, 0) -> 1 | AE35: =VLOOKUP(AC35, $AO$92:$AR$95, 3, 0) -> -9 | AF35: =VLOOKUP(AC35, $AO$92:$AR$95, 4, 0) -> 2 | AH35: 4 | AI35: =INDEX($AU$92:$AU$95, MATCH(LARGE($AY$92:$AY$95, AH35), $AY$92:$AY$95, 0)) -> Panamá | AJ35: =VLOOKUP(AI35, $AU$92:$AX$95, 2, 0) -> 0 | AK35: =VLOOKUP(AI35, $AU$92:$AX$95, 3, 0) -> -9 | AL35: =VLOOKUP(AI35, $AU$92:$AX$95, 4, 0) -> 2
A36: Jogo 18 | F36: 46189 | J36: Jogo 42 | O36: 46195 | S36: Jogo 66 | X36: 46200
A37: Iraque | B37: 0 | C37: X | D37: 3 | E37: Noruega | F37: 19:00 | G37: =IF(B37="", 0, IF(B37>D37, 3, IF(B37=D37, 1, 0))) -> 0 | H37: =IF(D37="", 0, IF(D37>B37, 3, IF(D37=B37, 1, 0))) -> 3 | J37: França | K37: 4 | L37: X | M37: 0 | N37: Iraque | O37: 18:00 | P37: =IF(K37="", 0, IF(K37>M37, 3, IF(K37=M37, 1, 0))) -> 3 | Q37: =IF(M37="", 0, IF(M37>K37, 3, IF(M37=K37, 1, 0))) -> 0 | S37: Egito | T37: 1 | U37: X | V37: 0 | W37: Irã | X37: 00:00 | Y37: =IF(T37="", 0, IF(T37>V37, 3, IF(T37=V37, 1, 0))) -> 3 | Z37: =IF(V37="", 0, IF(V37>T37, 3, IF(V37=T37, 1, 0))) -> 0 | AC37: TERCEIROS | AD37: P | AE37: SG | AF37: GP
A38: Jogo 19 | F38: 46189 | J38: Jogo 43 | O38: 46195 | S38: Jogo 67 | X38: 46200 | AB38: 1 | AC38: =INDEX($BC$80:$BC$91, MATCH(LARGE($BG$80:$BG$91, AB38), $BG$80:$BG$91, 0)) -> Arábia Saudita | AD38: =VLOOKUP(AC38, $BC$80:$BH$91, 2, 0) -> 4 | AE38: =VLOOKUP(AC38, $BC$80:$BH$91, 3, 0) -> 2 | AF38: =VLOOKUP(AC38, $BC$80:$BH$91, 4, 0) -> 5 | AG38: =VLOOKUP(AC38, $BC$80:$BH$91, 6, 0) -> H
A39: Argentina | B39: 2 | C39: X | D39: 0 | E39: Argélia | F39: 22:00 | G39: =IF(B39="", 0, IF(B39>D39, 3, IF(B39=D39, 1, 0))) -> 3 | H39: =IF(D39="", 0, IF(D39>B39, 3, IF(D39=B39, 1, 0))) -> 0 | J39: Noruega | K39: 2 | L39: X | M39: 2 | N39: Senegal | O39: 21:00 | P39: =IF(K39="", 0, IF(K39>M39, 3, IF(K39=M39, 1, 0))) -> 1 | Q39: =IF(M39="", 0, IF(M39>K39, 3, IF(M39=K39, 1, 0))) -> 1 | S39: Panamá | T39: 0 | U39: X | V39: 4 | W39: Inglaterra | X39: 18:00 | Y39: =IF(T39="", 0, IF(T39>V39, 3, IF(T39=V39, 1, 0))) -> 0 | Z39: =IF(V39="", 0, IF(V39>T39, 3, IF(V39=T39, 1, 0))) -> 3 | AB39: 2 | AC39: =INDEX($BC$80:$BC$91, MATCH(LARGE($BG$80:$BG$91, AB39), $BG$80:$BG$91, 0)) -> Suécia | AD39: =VLOOKUP(AC39, $BC$80:$BH$91, 2, 0) -> 4 | AE39: =VLOOKUP(AC39, $BC$80:$BH$91, 3, 0) -> -1 | AF39: =VLOOKUP(AC39, $BC$80:$BH$91, 4, 0) -> 4 | AG39: =VLOOKUP(AC39, $BC$80:$BH$91, 6, 0) -> F
A40: Jogo 20 | F40: 46190 | J40: Jogo 44 | O40: 46196 | S40: Jogo 68 | X40: 46200 | AB40: 3 | AC40: =INDEX($BC$80:$BC$91, MATCH(LARGE($BG$80:$BG$91, AB40), $BG$80:$BG$91, 0)) -> Senegal | AD40: =VLOOKUP(AC40, $BC$80:$BH$91, 2, 0) -> 4 | AE40: =VLOOKUP(AC40, $BC$80:$BH$91, 3, 0) -> -1 | AF40: =VLOOKUP(AC40, $BC$80:$BH$91, 4, 0) -> 4 | AG40: =VLOOKUP(AC40, $BC$80:$BH$91, 6, 0) -> I
...

Sheet Matriz
B1: 1A | C1: 1B | D1: 1D | E1: 1E | F1: 1G | G1: 1I | H1: 1K | I1: 1L
A2: 1 | B2: 3E | C2: 3J | D2: 3I | E2: 3F | F2: 3H | G2: 3G | H2: 3L | I2: 3K | J2: =COUNTIF($B2:$I2,"*A") & COUNTIF($B2:$I2,"*B") & COUNTIF($B2:$I2,"*C") & COUNTIF($B2:$I2,"*D") & COUNTIF($B2:$I2,"*E") & COUNTIF($B2:$I2,"*F") & COUNTIF($B2:$I2,"*G") & COUNTIF($B2:$I2,"*H") & COUNTIF($B2:$I2,"*I") & COUNTIF($B2:$I2,"*J") & COUNTIF($B2:$I2,"*K") & COUNTIF($B2:$I2,"*L") -> 000011111111
A3: 2 | B3: 3H | C3: 3G | D3: 3I | E3: 3D | F3: 3J | G3: 3F | H3: 3L | I3: 3K | J3: =COUNTIF($B3:$I3,"*A") & COUNTIF($B3:$I3,"*B") & COUNTIF($B3:$I3,"*C") & COUNTIF($B3:$I3,"*D") & COUNTIF($B3:$I3,"*E") & COUNTIF($B3:$I3,"*F") & COUNTIF($B3:$I3,"*G") & COUNTIF($B3:$I3,"*H") & COUNTIF($B3:$I3,"*I") & COUNTIF($B3:$I3,"*J") & COUNTIF($B3:$I3,"*K") & COUNTIF($B3:$I3,"*L") -> 000101111111
A4: 3 | B4: 3E | C4: 3J | D4: 3I | E4: 3D | F4: 3H | G4: 3G | H4: 3L | I4: 3K | J4: =COUNTIF($B4:$I4,"*A") & COUNTIF($B4:$I4,"*B") & COUNTIF($B4:$I4,"*C") & COUNTIF($B4:$I4,"*D") & COUNTIF($B4:$I4,"*E") & COUNTIF($B4:$I4,"*F") & COUNTIF($B4:$I4,"*G") & COUNTIF($B4:$I4,"*H") & COUNTIF($B4:$I4,"*I") & COUNTIF($B4:$I4,"*J") & COUNTIF($B4:$I4,"*K") & COUNTIF($B4:$I4,"*L") -> 000110111111
A5: 4 | B5: 3E | C5: 3J | D5: 3I | E5: 3D | F5: 3H | G5: 3F | H5: 3L | I5: 3K | J5: =COUNTIF($B5:$I5,"*A") & COUNTIF($B5:$I5,"*B") & COUNTIF($B5:$I5,"*C") & COUNTIF($B5:$I5,"*D") & COUNTIF($B5:$I5,"*E") & COUNTIF($B5:$I5,"*F") & COUNTIF($B5:$I5,"*G") & COUNTIF($B5:$I5,"*H") & COUNTIF($B5:$I5,"*I") & COUNTIF($B5:$I5,"*J") & COUNTIF($B5:$I5,"*K") & COUNTIF($B5:$I5,"*L") -> 000111011111
A6: 5 | B6: 3E | C6: 3G | D6: 3I | E6: 3D | F6: 3J | G6: 3F | H6: 3L | I6: 3K | J6: =COUNTIF($B6:$I6,"*A") & COUNTIF($B6:$I6,"*B") & COUNTIF($B6:$I6,"*C") & COUNTIF($B6:$I6,"*D") & COUNTIF($B6:$I6,"*E") & COUNTIF($B6:$I6,"*F") & COUNTIF($B6:$I6,"*G") & COUNTIF($B6:$I6,"*H") & COUNTIF($B6:$I6,"*I") & COUNTIF($B6:$I6,"*J") & COUNTIF($B6:$I6,"*K") & COUNTIF($B6:$I6,"*L") -> 000111101111
A7: 6 | B7: 3E | C7: 3G | D7: 3J | E7: 3D | F7: 3H | G7: 3F | H7: 3L | I7: 3K | J7: =COUNTIF($B7:$I7,"*A") & COUNTIF($B7:$I7,"*B") & COUNTIF($B7:$I7,"*C") & COUNTIF($B7:$I7,"*D") & COUNTIF($B7:$I7,"*E") & COUNTIF($B7:$I7,"*F") & COUNTIF($B7:$I7,"*G") & COUNTIF($B7:$I7,"*H") & COUNTIF($B7:$I7,"*I") & COUNTIF($B7:$I7,"*J") & COUNTIF($B7:$I7,"*K") & COUNTIF($B7:$I7,"*L") -> 000111110111
A8: 7 | B8: 3E | C8: 3G | D8: 3I | E8: 3D | F8: 3H | G8: 3F | H8: 3L | I8: 3K | J8: =COUNTIF($B8:$I8,"*A") & COUNTIF($B8:$I8,"*B") & COUNTIF($B8:$I8,"*C") & COUNTIF($B8:$I8,"*D") & COUNTIF($B8:$I8,"*E") & COUNTIF($B8:$I8,"*F") & COUNTIF($B8:$I8,"*G") & COUNTIF($B8:$I8,"*H") & COUNTIF($B8:$I8,"*I") & COUNTIF($B8:$I8,"*J") & COUNTIF($B8:$I8,"*K") & COUNTIF($B8:$I8,"*L") -> 000111111011
A9: 8 | B9: 3E | C9: 3G | D9: 3J | E9: 3D | F9: 3H | G9: 3F | H9: 3L | I9: 3I | J9: =COUNTIF($B9:$I9,"*A") & COUNTIF($B9:$I9,"*B") & COUNTIF($B9:$I9,"*C") & COUNTIF($B9:$I9,"*D") & COUNTIF($B9:$I9,"*E") & COUNTIF($B9:$I9,"*F") & COUNTIF($B9:$I9,"*G") & COUNTIF($B9:$I9,"*H") & COUNTIF($B9:$I9,"*I") & COUNTIF($B9:$I9,"*J") & COUNTIF($B9:$I9,"*K") & COUNTIF($B9:$I9,"*L") -> 000111111101
A10: 9 | B10: 3E | C10: 3G | D10: 3J | E10: 3D | F10: 3H | G10: 3F | H10: 3I | I10: 3K | J10: =COUNTIF($B10:$I10,"*A") & COUNTIF($B10:$I10,"*B") & COUNTIF($B10:$I10,"*C") & COUNTIF($B10:$I10,"*D") & COUNTIF($B10:$I10,"*E") & COUNTIF($B10:$I10,"*F") & COUNTIF($B10:$I10,"*G") & COUNTIF($B10:$I10,"*H") & COUNTIF($B10:$I10,"*I") & COUNTIF($B10:$I10,"*J") & COUNTIF($B10:$I10,"*K") & COUNTIF($B10:$I10,"*L") -> 000111111110
A11: 10 | B11: 3H | C11: 3G | D11: 3I | E11: 3C | F11: 3J | G11: 3F | H11: 3L | I11: 3K | J11: =COUNTIF($B11:$I11,"*A") & COUNTIF($B11:$I11,"*B") & COUNTIF($B11:$I11,"*C") & COUNTIF($B11:$I11,"*D") & COUNTIF($B11:$I11,"*E") & COUNTIF($B11:$I11,"*F") & COUNTIF($B11:$I11,"*G") & COUNTIF($B11:$I11,"*H") & COUNTIF($B11:$I11,"*I") & COUNTIF($B11:$I11,"*J") & COUNTIF($B11:$I11,"*K") & COUNTIF($B11:$I11,"*L") -> 001001111111
A12: 11 | B12: 3E | C12: 3J | D12: 3I | E12: 3C | F12: 3H | G12: 3G | H12: 3L | I12: 3K | J12: =COUNTIF($B12:$I12,"*A") & COUNTIF($B12:$I12,"*B") & COUNTIF($B12:$I12,"*C") & COUNTIF($B12:$I12,"*D") & COUNTIF($B12:$I12,"*E") & COUNTIF($B12:$I12,"*F") & COUNTIF($B12:$I12,"*G") & COUNTIF($B12:$I12,"*H") & COUNTIF($B12:$I12,"*I") & COUNTIF($B12:$I12,"*J") & COUNTIF($B12:$I12,"*K") & COUNTIF($B12:$I12,"*L") -> 001010111111
A13: 12 | B13: 3E | C13: 3J | D13: 3I | E13: 3C | F13: 3H | G13: 3F | H13: 3L | I13: 3K | J13: =COUNTIF($B13:$I13,"*A") & COUNTIF($B13:$I13,"*B") & COUNTIF($B13:$I13,"*C") & COUNTIF($B13:$I13,"*D") & COUNTIF($B13:$I13,"*E") & COUNTIF($B13:$I13,"*F") & COUNTIF($B13:$I13,"*G") & COUNTIF($B13:$I13,"*H") & COUNTIF($B13:$I13,"*I") & COUNTIF($B13:$I13,"*J") & COUNTIF($B13:$I13,"*K") & COUNTIF($B13:$I13,"*L") -> 001011011111
... A496: 495 | B496: 3H | C496: 3G | D496: 3B | E496: 3C | F496: 3A | G496: 3F | H496: 3D | I496: 3E | J496: =COUNTIF($B496:$I496,"*A") & COUNTIF($B496:$I496,"*B") & COUNTIF($B496:$I496,"*C") & COUNTIF($B496:$I496,"*D") & COUNTIF($B496:$I496,"*E") & COUNTIF($B496:$I496,"*F") & COUNTIF($B496:$I496,"*G") & COUNTIF($B496:$I496,"*H") & COUNTIF($B496:$I496,"*I") & COUNTIF($B496:$I496,"*J") & COUNTIF($B496:$I496,"*K") & COUNTIF($B496:$I496,"*L") -> 111111110000
